Workbook
Name Apartments_Abatement: Assumptions!$C$28
Name Apartments_Abatement_A: Assumptions!$C$37
Name Apartments_Base_Val: Assumptions!$B$7
Name Apartments_CDC: Assumptions!$E$28
Name Apartments_CDC_A: Assumptions!$E$37
Name Apartments_Impvt_Val: Assumptions!$B$10
Name Apartments_Land_Growth: Assumptions!$B$9
Name Apartments_Non_abated: Assumptions!$D$28
Name Apartments_Non_abated_A: Assumptions!$D$37
Name Apartments_Retained: Assumptions!$F$28
Name Apartments_Retained_A: Assumptions!$F$37
Name Apartments_Term: Assumptions!$B$28
Name Apartments_Term_A: Assumptions!$B$37
Name Condos_Base_Val: Assumptions!$D$18
Name Condos_Impvt_Val: Assumptions!$D$21
Name Condos_Land_Growth: Assumptions!$D$20
Name Full_Comm_Rate_A: Assumptions!$K$28
Name Full_Comm_Rate_B: Assumptions!$K$32
Name Full_Res_Rate_A: Assumptions!$J$28
Name Full_Res_Rate_B: Assumptions!$J$32
Name Hilliard_Abatement: Assumptions!$A$26:$F$33
Name Hilliard_Abatement_C: Assumptions!$A$26:$A$33
Name Hilliard_Abatement_R: Assumptions!$A$26:$F$26
Name Hilliard_Rates: Assumptions!$I$25:$K$28
Name Hotel_Abatement: Assumptions!$C$33
Name Hotel_Abatement_A: Assumptions!$C$42
Name Hotel_CDC: Assumptions!$E$33
Name Hotel_CDC_A: Assumptions!$E$42
Name Hotel_Non_abated: Assumptions!$D$33
Name Hotel_Non_abated_A: Assumptions!$D$42
Name Hotel_Retained: Assumptions!$F$33
Name Hotel_Retained_A: Assumptions!$F$42
Name Hotel_Term: Assumptions!$B$33
Name Hotel_Term_A: Assumptions!$B$42
Name Land_Growth_Abatement: Assumptions!$C$27
Name Land_Growth_Abatement_A: Assumptions!$C$36
Name Land_Growth_CDC: Assumptions!$E$27
Name Land_Growth_CDC_A: Assumptions!$E$36
Name Land_Growth_Non_abated: Assumptions!$D$27
Name Land_Growth_Non_abated_A: Assumptions!$D$36
Name Land_Growth_Retained: Assumptions!$F$27
Name Land_Growth_Retained_A: Assumptions!$F$36
Name Land_Growth_Term: Assumptions!$B$27
Name Land_Growth_Term_A: Assumptions!$B$36
Name Non_School_Comm_Rate_A: Assumptions!$K$27
Name Non_School_Comm_Rate_B: Assumptions!$K$31
Name Non_School_Res_Rate_A: Assumptions!$J$27
Name Non_School_Res_Rate_B: Assumptions!$J$31
Name Office_Abatement: Assumptions!$C$30
Name Office_Abatement_A: Assumptions!$C$39
Name Office_Base_Val: Assumptions!$B$18
Name Office_CDC: Assumptions!$E$30
Name Office_CDC_A: Assumptions!$E$39
Name Office_Impvt_Val: Assumptions!$B$21
Name Office_Land_Growth: Assumptions!$B$20
Name Office_Non_abated: Assumptions!$D$30
Name Office_Non_abated_A: Assumptions!$D$39
Name Office_Retained: Assumptions!$F$30
Name Office_Retained_A: Assumptions!$F$39
Name Office_Term: Assumptions!$B$30

Sheet Assumptions
A1: Development Composition | E1: BOND ASSUMPTIONS AND REVENUE SUMMARY
A2: Apartments | C2: Single-Family Homes | E2: A Bond
A3: Completion | B3: 2022 | C3: Completion | D3: 2023 | E3: NPV | F3: 0.0325 | G3: =NPV(F3,'Revenue Summary'!B16:AE16) -> 16381326
A4: Acreage | B4: 10.38 | C4: Acreage | D4: 4.28 | E4: Cap int | F4: 0.05 | G4: =-G3*F4 -> -819066.32
A5: Units or SF | B5: 293 | C5: Units or SF | D5: 12 | E5: Issuance | F5: 0.04 | G5: =-G3*F5 -> -655253.05
A6: Value per unit | B6: 132000 | C6: Value per unit | D6: 750000 | E6: Reserve | F6: 0.1 | G6: =G3*F6*-1 -> -1638132.6
A7: Base Value | B7: =H28*B4 -> 869325 | C7: Base Value | D7: =H28*D4 -> 358450 | E7: Total | G7: =SUM(G3:G6) -> 13268874
A8: Prelim. Impvmt Value | B8: =B5*B6-B7 -> 37806675 | C8: Prelim. Impvmt Value | D8: =D5*D6-D7 -> 8641550
A9: Land Growth | B9: =$H$30*B8 -> 4536801 | C9: Land Growth | D9: =$H$30*D8 -> 1036986 | E9: Surplus
A10: Improvement Value | B10: =B8-B9 -> 33269874 | C10: Improvement Value | D10: =D8-D9 -> 7604564 | E10: Rate | F10: 0.09 | G10: =NPV(F3,'Revenue Summary'!B19:AE19) -> 1638132.6
A11: Total Value | B11: =SUM(B7,B9,B10) -> 38676000 | C11: Total Value | D11: =SUM(D7,D9,D10) -> 9000000 | E11: Issuance | F11: =F4 -> 0.05 | G11: =-G10*F11 -> -81906.632
E12: Cap int | F12: =F5 -> 0.04 | G12: =-G10*F12 -> -65525.305
A13: Office | C13: Condos | E13: Reserve | F13: =F6 -> 0.1 | G13: =G10*F13*-1 -> -163813.26
A14: Completion | B14: 2022 | C14: Completion | D14: 2023 | E14: Total | G14: =SUM(G10:G13) -> 1326887.4
A15: Acreage | B15: 1.67 | C15: Acreage | D15: 1.0585714 | E15: DEBT COVERAGE RATIO
A16: Units or SF | B16: 43000 | C16: Units or SF | D16: 31 | E16: Ratio | G16: 1.1
A17: Value per unit | B17: 160 | C17: Value per unit | D17: 550000 | E17: Revenue
A18: Base Value | B18: =H28*B15 -> 139862.5 | C18: Base Value | D18: =H28*D15 -> 88655.357 | F18: A Bonds | G18: Surplus
A19: Prelim. Impvmt Value | B19: =B16*B17-B18 -> 6740137.5 | C19: Prelim. Impvmt Value | D19: =D16*D17-D18 -> 16961345 | E19: Gross Revenue Bond Sale | F19: =G3 -> 16381326 | G19: =G10 -> 1638132.6
A20: Land Growth | B20: =$H$30*B19 -> 808816.5 | C20: Land Growth | D20: =$H$30*D19 -> 2035361.4 | E20: Net Rev NCA | F20: =G7 -> 13268874 | G20: =G14 -> 1326887.4
A21: Improvement Value | B21: =B19-B20 -> 5931321 | C21: Improvement Value | D21: =D19-D20 -> 14925983
A22: Total Value | B22: =SUM(B18,B20,B21) -> 6880000 | C22: Total Value | D22: =SUM(D18,D20,D21) -> 17050000 | E22: Total revenue to NCA | F22: =G7+G14 -> 14595762 | G22: =F22/$F$22 -> 1
A25: Abatement Structure | B25: Municipality A | G25: Development Base Value Details | I25: Municipality A, Tax Rates | J25: Residential | K25: Commercial
A26: Use | B26: Term (years) | C26: Abatement | D26: Non-abated | E26: CDC | F26: Retained | G26: Total acres | H26: 80 | I26: School | J26: 0.057772736 | K26: 0.066633322
A27: Land Growth | B27: 10 | C27: 1 | D27: =1-C27 -> 0 | E27: 0.5 | F27: =IF((C27-D27-E27)<0,0,(C27-D27-E27)) -> 0.5 | G27: Base value | H27: 6700000 | I27: Non-school | J27: 0.022720332 | K27: 0.023702183
A28: Apartments | B28: 15 | C28: 1 | D28: =1-C28 -> 0 | E28: 0.5 | F28: =IF((C28-E28)<0,0,(C28-E28)) -> 0.5 | G28: Base per acre | H28: =H27/H26 -> 83750 | I28: Total | J28: =SUM(J26:J27) -> 0.080493068 | K28: =SUM(K26:K27) -> 0.090335505
A29: For Sale Residential | B29: 15 | C29: 1 | D29: =1-C29 -> 0 | E29: 0.5 | F29: =IF((C29-E29)<0,0,(C29-E29)) -> 0.5 | I29: Municipality B, Tax Rates | J29: Residential | K29: Commercial
A30: Office | B30: 10 | C30: 0.75 | D30: =1-C30 -> 0.25 | E30: 0.25 | F30: =IF((C30-E30)<0,0,(C30-E30)) -> 0.5 | G30: Land growth factor | H30: 0.12 | I30: School | J30: 0 | K30: 0
A31: Retail | B31: 0 | C31: 0 | D31: =1-C31 -> 1 | E31: 0 | F31: =IF((C31-E31)<0,0,(C31-E31)) -> 0 | I31: Non-school | J31: 0 | K31: 0
A32: Senior Apartments | B32: 15 | C32: 1 | D32: =1-C32 -> 0 | E32: 0.5 | F32: =IF((C32-E32)<0,0,(C32-E32)) -> 0.5 | I32: Total | J32: =SUM(J30:J31) -> 0 | K32: =SUM(K30:K31) -> 0
A33: Hotel | B33: 0 | C33: 0 | D33: =1-C33 -> 1 | E33: 0 | F33: =IF((C33-E33)<0,0,(C33-E33)) -> 0
A34: Abatement Structure | B34: Municipality B | G34: Minor Re-Appraisal | H34: 0.03
A35: Use | B35: Term (years) | C35: Abatement | D35: Non-abated | E35: CDC | F35: Retained | G35: Major Re-Appraisal | H35: 0.06
A36: Land Growth | B36: 10 | C36: 1 | D36: =1-C36 -> 0 | E36: 0.5 | F36: =IF((C36-D36-E36)<0,0,(C36-D36-E36)) -> 0.5
A37: Apartments | B37: 15 | C37: 1 | D37: =1-C37 -> 0 | E37: 0.5 | F37: =IF((C37-E37)<0,0,(C37-E37)) -> 0.5
A38: For Sale Residential | B38: 15 | C38: 1 | D38: =1-C38 -> 0 | E38: 0.5 | F38: =IF((C38-E38)<0,0,(C38-E38)) -> 0.5
A39: Office | B39: 10 | C39: 0.75 | D39: =1-C39 -> 0.25 | E39: 0.25 | F39: =IF((C39-E39)<0,0,(C39-E39)) -> 0.5
A40: Retail | B40: 0 | C40: 0 | D40: =1-C40 -> 1 | E40: 0 | F40: =IF((C40-E40)<0,0,(C40-E40)) -> 0
A41: Senior Apartments | B41: 15 | C41: 1 | D41: =1-C41 -> 0 | E41: 0.5 | F41: =IF((C41-E41)<0,0,(C41-E41)) -> 0.5
A42: Hotel | B42: 0 | C42: 0 | D42: =1-C42 -> 1 | E42: 0 | F42: =IF((C42-E42)<0,0,(C42-E42)) -> 0

Sheet Calculations
A1: Tax Year | B1: 2020 | C1: =B1+1 -> 2021 | D1: =C1+1 -> 2022 | E1: =D1+1 -> 2023 | F1: =E1+1 -> 2024 | G1: =F1+1 -> 2025 | H1: =G1+1 -> 2026 | I1: =H1+1 -> 2027 | J1: =I1+1 -> 2028 | ... AE1: =AD1+1 -> 2049
A2: Collection Year | B2: =B1+1 -> 2021 | C2: =C1+1 -> 2022 | D2: =D1+1 -> 2023 | E2: =E1+1 -> 2024 | F2: =F1+1 -> 2025 | G2: =G1+1 -> 2026 | H2: =H1+1 -> 2027 | I2: =I1+1 -> 2028 | ... AE2: =AE1+1 -> 2050
A3: Inflation factor | B3: =Assumptions!$H$34 -> 0.03 | C3: 0 | D3: 0 | E3: =Assumptions!$H$35 -> 0.06 | F3: 0 | G3: 0 | H3: =B3 -> 0.03 | I3: 0 | J3: 0 | K3: =E3 -> 0.06 | L3: 0 | M3: 0 | N3: =H3 -> 0.03 | O3: 0 | P3: 0 | Q3: =K3 -> 0.06 | R3: 0 | S3: 0 | T3: =N3 -> 0.03 | U3: 0 | V3: 0 | W3: =Q3 -> 0.06 | X3: 0 | Y3: 0 | Z3: =T3 -> 0.03 | AA3: 0 | AB3: 0 | AC3: =W3 -> 0.06 | AD3: 0 | AE3: 0
A4: Cumulative inflation | B4: =SUM($B$3:B3) -> 0.03 | C4: =B4 -> 0.03 | D4: =B4 -> 0.03 | E4: =((1+B4)*(1+E3))-1 -> 0.0918 | F4: =E4 -> 0.0918 | G4: =E4 -> 0.0918 | H4: =((1+E4)*(1+H3))-1 -> 0.124554 | I4: =H4 -> 0.124554 | J4: =H4 -> 0.124554 | K4: =((1+H4)*(1+K3))-1 -> 0.19202724 | L4: =K4 -> 0.19202724 | M4: =K4 -> 0.19202724 | N4: =((1+K4)*(1+N3))-1 -> 0.22778806 | O4: =N4 -> 0.22778806 | P4: =N4 -> 0.22778806 | Q4: =((1+N4)*(1+Q3))-1 -> 0.30145534 | R4: =Q4 -> 0.30145534 | S4: =Q4 -> 0.30145534 | T4: =((1+Q4)*(1+T3))-1 -> 0.340499 | U4: =T4 -> 0.340499 | V4: =T4 -> 0.340499 | W4: =((1+T4)*(1+W3))-1 -> 0.42092894 | X4: =W4 -> 0.42092894 | Y4: =W4 -> 0.42092894 | Z4: =((1+W4)*(1+Z3))-1 -> 0.46355681 | AA4: =Z4 -> 0.46355681 | AB4: =Z4 -> 0.46355681 | AC4: =((1+Z4)*(1+AC3))-1 -> 0.55137022 | AD4: =AC4 -> 0.55137022 | AE4: =AC4 -> 0.55137022
A6: =Assumptions!$A$2 -> Apartments
A7: Land abatement year | B7: =IF(Land_Growth_Term>0,1) -> 1 | C7: =IF(Land_Growth_Term>0,B7+1) -> 2 | D7: =IF(Land_Growth_Term>0,C7+1) -> 3 | E7: =IF(Land_Growth_Term>0,D7+1) -> 4 | F7: =IF(Land_Growth_Term>0,E7+1) -> 5 | G7: =IF(Land_Growth_Term>0,F7+1) -> 6 | H7: =IF(Land_Growth_Term>0,G7+1) -> 7 | I7: =IF(Land_Growth_Term>0,H7+1) -> 8 | J7: =IF(Land_Growth_Term>0,I7+1) -> 9 | K7: =IF(Land_Growth_Term>0,J7+1) -> 10
A8: Building abatement year | B8: =IF(Assumptions!$B$3>=B$2,0,IF(Assumptions!$B$3+1=B$2,1,IF(Assumptions!$B$3+15>=B$2,A8+1,0))) -> 0 | C8: =IF(Assumptions!$B$3>=C$2,0,IF(Assumptions!$B$3+1=C$2,1,IF(Assumptions!$B$3+15>=C$2,B8+1,0))) -> 0 | D8: =IF(Assumptions!$B$3>=D$2,0,IF(Assumptions!$B$3+1=D$2,1,IF(Assumptions!$B$3+15>=D$2,C8+1,0))) -> 1 | E8: =IF(Assumptions!$B$3>=E$2,0,IF(Assumptions!$B$3+1=E$2,1,IF(Assumptions!$B$3+15>=E$2,D8+1,0))) -> 2 | F8: =IF(Assumptions!$B$3>=F$2,0,IF(Assumptions!$B$3+1=F$2,1,IF(Assumptions!$B$3+15>=F$2,E8+1,0))) -> 3 | G8: =IF(Assumptions!$B$3>=G$2,0,IF(Assumptions!$B$3+1=G$2,1,IF(Assumptions!$B$3+15>=G$2,F8+1,0))) -> 4 | H8: =IF(Assumptions!$B$3>=H$2,0,IF(Assumptions!$B$3+1=H$2,1,IF(Assumptions!$B$3+15>=H$2,G8+1,0))) -> 5 | I8: =IF(Assumptions!$B$3>=I$2,0,IF(Assumptions!$B$3+1=I$2,1,IF(Assumptions!$B$3+15>=I$2,H8+1,0))) -> 6 | ... AE8: =IF(Assumptions!$B$3>=AE$2,0,IF(Assumptions!$B$3+1=AE$2,1,IF(Assumptions!$B$3+15>=AE$2,AD8+1,0))) -> 0
A9: Base value | B9: =Apartments_Base_Val -> 869325 | C9: =B9 -> 869325 | D9: =C9 -> 869325 | E9: =D9 -> 869325 | F9: =E9 -> 869325 | G9: =F9 -> 869325 | H9: =G9 -> 869325 | I9: =H9 -> 869325 | J9: =I9 -> 869325 | ... AE9: =AD9 -> 869325
A10: Land growth | B10: =IF(B$2<=Assumptions!$B$3,0,IF(B$2=Assumptions!$B$3+1,Apartments_Land_Growth*(1+B$4),IF(B$2>Assumptions!$B$3,A10*(1+B$3),0))) -> 0 | C10: =IF(C$2<=Assumptions!$B$3,0,IF(C$2=Assumptions!$B$3+1,Apartments_Land_Growth*(1+C$4),IF(C$2>Assumptions!$B$3,B10*(1+C$3),0))) -> 0 | D10: =IF(D$2<=Assumptions!$B$3,0,IF(D$2=Assumptions!$B$3+1,Apartments_Land_Growth*(1+D$4),IF(D$2>Assumptions!$B$3,C10*(1+D$3),0))) -> 4672905 | E10: =IF(E$2<=Assumptions!$B$3,0,IF(E$2=Assumptions!$B$3+1,Apartments_Land_Growth*(1+E$4),IF(E$2>Assumptions!$B$3,D10*(1+E$3),0))) -> 4953279.3 | F10: =IF(F$2<=Assumptions!$B$3,0,IF(F$2=Assumptions!$B$3+1,Apartments_Land_Growth*(1+F$4),IF(F$2>Assumptions!$B$3,E10*(1+F$3),0))) -> 4953279.3 | G10: =IF(G$2<=Assumptions!$B$3,0,IF(G$2=Assumptions!$B$3+1,Apartments_Land_Growth*(1+G$4),IF(G$2>Assumptions!$B$3,F10*(1+G$3),0))) -> 4953279.3 | H10: =IF(H$2<=Assumptions!$B$3,0,IF(H$2=Assumptions!$B$3+1,Apartments_Land_Growth*(1+H$4),IF(H$2>Assumptions!$B$3,G10*(1+H$3),0))) -> 5101877.7 | I10: =IF(I$2<=Assumptions!$B$3,0,IF(I$2=Assumptions!$B$3+1,Apartments_Land_Growth*(1+I$4),IF(I$2>Assumptions!$B$3,H10*(1+I$3),0))) -> 5101877.7 | ... AE10: =IF(AE$2<=Assumptions!$B$3,0,IF(AE$2=Assumptions!$B$3+1,Apartments_Land_Growth*(1+AE$4),IF(AE$2>Assumptions!$B$3,AD10*(1+AE$3),0))) -> 7038258
A11: Improvement value | B11: =IF(B$2<=Assumptions!$B$3,0,IF(B$2=Assumptions!$B$3+1,Apartments_Impvt_Val*(1+B$4),IF(B$2>Assumptions!$B$3,A11*(1+B$3),0))) -> 0 | C11: =IF(C$2<=Assumptions!$B$3,0,IF(C$2=Assumptions!$B$3+1,Apartments_Impvt_Val*(1+C$4),IF(C$2>Assumptions!$B$3,B11*(1+C$3),0))) -> 0 | D11: =IF(D$2<=Assumptions!$B$3,0,IF(D$2=Assumptions!$B$3+1,Apartments_Impvt_Val*(1+D$4),IF(D$2>Assumptions!$B$3,C11*(1+D$3),0))) -> 34267970 | E11: =IF(E$2<=Assumptions!$B$3,0,IF(E$2=Assumptions!$B$3+1,Apartments_Impvt_Val*(1+E$4),IF(E$2>Assumptions!$B$3,D11*(1+E$3),0))) -> 36324048 | F11: =IF(F$2<=Assumptions!$B$3,0,IF(F$2=Assumptions!$B$3+1,Apartments_Impvt_Val*(1+F$4),IF(F$2>Assumptions!$B$3,E11*(1+F$3),0))) -> 36324048 | G11: =IF(G$2<=Assumptions!$B$3,0,IF(G$2=Assumptions!$B$3+1,Apartments_Impvt_Val*(1+G$4),IF(G$2>Assumptions!$B$3,F11*(1+G$3),0))) -> 36324048 | H11: =IF(H$2<=Assumptions!$B$3,0,IF(H$2=Assumptions!$B$3+1,Apartments_Impvt_Val*(1+H$4),IF(H$2>Assumptions!$B$3,G11*(1+H$3),0))) -> 37413770 | I11: =IF(I$2<=Assumptions!$B$3,0,IF(I$2=Assumptions!$B$3+1,Apartments_Impvt_Val*(1+I$4),IF(I$2>Assumptions!$B$3,H11*(1+I$3),0))) -> 37413770 | ... AE11: =IF(AE$2<=Assumptions!$B$3,0,IF(AE$2=Assumptions!$B$3+1,Apartments_Impvt_Val*(1+AE$4),IF(AE$2>Assumptions!$B$3,AD11*(1+AE$3),0))) -> 51613892
A12: Full Value Tax
A13: Full value | B13: =SUM(B9:B11) -> 869325 | C13: =SUM(C9:C11) -> 869325 | D13: =SUM(D9:D11) -> 39810200 | E13: =SUM(E9:E11) -> 42146653 | F13: =SUM(F9:F11) -> 42146653 | G13: =SUM(G9:G11) -> 42146653 | H13: =SUM(H9:H11) -> 43384973 | I13: =SUM(I9:I11) -> 43384973 | ... AE13: =SUM(AE9:AE11) -> 59521475
A14: Full tax | B14: =B13*0.35*Full_Comm_Rate_A -> 27485.82 | C14: =C13*0.35*Full_Comm_Rate_A -> 27485.82 | D14: =D13*0.35*Full_Comm_Rate_A -> 1258696.1 | E14: =E13*0.35*Full_Comm_Rate_A -> 1332568.7 | F14: =F13*0.35*Full_Comm_Rate_A -> 1332568.7 | G14: =G13*0.35*Full_Comm_Rate_A -> 1332568.7 | H14: =H13*0.35*Full_Comm_Rate_A -> 1371721.2 | I14: =I13*0.35*Full_Comm_Rate_A -> 1371721.2 | ... AE14: =AE13*0.35*Full_Comm_Rate_A -> 1881915.9
A15: Collection Items
A16: Tax to school | B16: =IF(AND(B7=0,B8=0),(B9*0.35*School_Comm_Rate_A)+(B10*0.35*School_Comm_Rate_A)+(B11*0.35*School_Comm_Rate_A),IF(AND(B7=0,B8>0),(B9*0.35*School_Comm_Rate_A)+(B10*0.35*School_Comm_Rate_A)+(B11*Apartments_Non_abated*0.35*School_Comm_Rate_A),IF(AND(B7>0,B8=0),(B9*0.35*School_Comm_Rate_A)+(B10*Land_Growth_Non_abated*0.35*School_Comm_Rate_A)+(B11*0.35*School_Comm_Rate_A),IF(AND(B7>0,B8>0),(B9*0.35*School_Comm_Rate_A)+(B10*Land_Growth_Non_abated*0.35*School_Comm_Rate_A)+(B11*Apartments_Non_abated*0.35*School_Comm_Rate_A),0)))) -> 20274.104 | C16: =IF(AND(C7=0,C8=0),(C9*0.35*School_Comm_Rate_A)+(C10*0.35*School_Comm_Rate_A)+(C11*0.35*School_Comm_Rate_A),IF(AND(C7=0,C8>0),(C9*0.35*School_Comm_Rate_A)+(C10*0.35*School_Comm_Rate_A)+(C11*Apartments_Non_abated*0.35*School_Comm_Rate_A),IF(AND(C7>0,C8=0),(C9*0.35*School_Comm_Rate_A)+(C10*Land_Growth_Non_abated*0.35*School_Comm_Rate_A)+(C11*0.35*School_Comm_Rate_A),IF(AND(C7>0,C8>0),(C9*0.35*School_Comm_Rate_A)+(C10*Land_Growth_Non_abated*0.35*School_Comm_Rate_A)+(C11*Apartments_Non_abated*0.35*School_Comm_Rate_A),0)))) -> 20274.104 | D16: =IF(AND(D7=0,D8=0),(D9*0.35*School_Comm_Rate_A)+(D10*0.35*School_Comm_Rate_A)+(D11*0.35*School_Comm_Rate_A),IF(AND(D7=0,D8>0),(D9*0.35*School_Comm_Rate_A)+(D10*0.35*School_Comm_Rate_A)+(D11*Apartments_Non_abated*0.35*School_Comm_Rate_A),IF(AND(D7>0,D8=0),(D9*0.35*School_Comm_Rate_A)+(D10*Land_Growth_Non_abated*0.35*School_Comm_Rate_A)+(D11*0.35*School_Comm_Rate_A),IF(AND(D7>0,D8>0),(D9*0.35*School_Comm_Rate_A)+(D10*Land_Growth_Non_abated*0.35*School_Comm_Rate_A)+(D11*Apartments_Non_abated*0.35*School_Comm_Rate_A),0)))) -> 20274.104 | E16: =IF(AND(E7=0,E8=0),(E9*0.35*School_Comm_Rate_A)+(E10*0.35*School_Comm_Rate_A)+(E11*0.35*School_Comm_Rate_A),IF(AND(E7=0,E8>0),(E9*0.35*School_Comm_Rate_A)+(E10*0.35*School_Comm_Rate_A)+(E11*Apartments_Non_abated*0.35*School_Comm_Rate_A),IF(AND(E7>0,E8=0),(E9*0.35*School_Comm_Rate_A)+(E10*Land_Growth_Non_abated*0.35*School_Comm_Rate_A)+(E11*0.35*School_Comm_Rate_A),IF(AND(E7>0,E8>0),(E9*0.35*School_Comm_Rate_A)+(E10*Land_Growth_Non_abated*0.35*School_Comm_Rate_A)+(E11*Apartments_Non_abated*0.35*School_Comm_Rate_A),0)))) -> 20274.104 | F16: =IF(AND(F7=0,F8=0),(F9*0.35*School_Comm_Rate_A)+(F10*0.35*School_Comm_Rate_A)+(F11*0.35*School_Comm_Rate_A),IF(AND(F7=0,F8>0),(F9*0.35*School_Comm_Rate_A)+(F10*0.35*School_Comm_Rate_A)+(F11*Apartments_Non_abated*0.35*School_Comm_Rate_A),IF(AND(F7>0,F8=0),(F9*0.35*School_Comm_Rate_A)+(F10*Land_Growth_Non_abated*0.35*School_Comm_Rate_A)+(F11*0.35*School_Comm_Rate_A),IF(AND(F7>0,F8>0),(F9*0.35*School_Comm_Rate_A)+(F10*Land_Growth_Non_abated*0.35*School_Comm_Rate_A)+(F11*Apartments_Non_abated*0.35*School_Comm_Rate_A),0)))) -> 20274.104 | G16: =IF(AND(G7=0,G8=0),(G9*0.35*School_Comm_Rate_A)+(G10*0.35*School_Comm_Rate_A)+(G11*0.35*School_Comm_Rate_A),IF(AND(G7=0,G8>0),(G9*0.35*School_Comm_Rate_A)+(G10*0.35*School_Comm_Rate_A)+(G11*Apartments_Non_abated*0.35*School_Comm_Rate_A),IF(AND(G7>0,G8=0),(G9*0.35*School_Comm_Rate_A)+(G10*Land_Growth_Non_abated*0.35*School_Comm_Rate_A)+(G11*0.35*School_Comm_Rate_A),IF(AND(G7>0,G8>0),(G9*0.35*School_Comm_Rate_A)+(G10*Land_Growth_Non_abated*0.35*School_Comm_Rate_A)+(G11*Apartments_Non_abated*0.35*School_Comm_Rate_A),0)))) -> 20274.104 | H16: =IF(AND(H7=0,H8=0),(H9*0.35*School_Comm_Rate_A)+(H10*0.35*School_Comm_Rate_A)+(H11*0.35*School_Comm_Rate_A),IF(AND(H7=0,H8>0),(H9*0.35*School_Comm_Rate_A)+(H10*0.35*School_Comm_Rate_A)+(H11*Apartments_Non_abated*0.35*School_Comm_Rate_A),IF(AND(H7>0,H8=0),(H9*0.35*School_Comm_Rate_A)+(H10*Land_Growth_Non_abated*0.35*School_Comm_Rate_A)+(H11*0.35*School_Comm_Rate_A),IF(AND(H7>0,H8>0),(H9*0.35*School_Comm_Rate_A)+(H10*Land_Growth_Non_abated*0.35*School_Comm_Rate_A)+(H11*Apartments_Non_abated*0.35*School_Comm_Rate_A),0)))) -> 20274.104 | I16: =IF(AND(I7=0,I8=0),(I9*0.35*School_Comm_Rate_A)+(I10*0.35*School_Comm_Rate_A)+(I11*0.35*School_Comm_Rate_A),IF(AND(I7=0,I8>0),(I9*0.35*School_Comm_Rate_A)+(I10*0.35*School_Comm_Rate_A)+(I11*Apartments_Non_abated*0.35*School_Comm_Rate_A),IF(AND(I7>0,I8=0),(I9*0.35*School_Comm_Rate_A)+(I10*Land_Growth_Non_abated*0.35*School_Comm_Rate_A)+(I11*0.35*School_Comm_Rate_A),IF(AND(I7>0,I8>0),(I9*0.35*School_Comm_Rate_A)+(I10*Land_Growth_Non_abated*0.35*School_Comm_Rate_A)+(I11*Apartments_Non_abated*0.35*School_Comm_Rate_A),0)))) -> 20274.104 | ... AE16: =IF(AND(AE7=0,AE8=0),(AE9*0.35*School_Comm_Rate_A)+(AE10*0.35*School_Comm_Rate_A)+(AE11*0.35*School_Comm_Rate_A),IF(AND(AE7=0,AE8>0),(AE9*0.35*School_Comm_Rate_A)+(AE10*0.35*School_Comm_Rate_A)+(AE11*Apartments_Non_abated*0.35*School_Comm_Rate_A),IF(AND(AE7>0,AE8=0),(AE9*0.35*School_Comm_Rate_A)+(AE10*Land_Growth_Non_abated*0.35*School_Comm_Rate_A)+(AE11*0.35*School_Comm_Rate_A),IF(AND(AE7>0,AE8>0),(AE9*0.35*School_Comm_Rate_A)+(AE10*Land_Growth_Non_abated*0.35*School_Comm_Rate_A)+(AE11*Apartments_Non_abated*0.35*School_Comm_Rate_A),0)))) -> 1388139.8
A17: Tax to non school | B17: =(B9*0.35*Non_School_Comm_Rate_A) -> 7211.7151 | C17: =(C9*0.35*Non_School_Comm_Rate_A) -> 7211.7151 | D17: =(D9*0.35*Non_School_Comm_Rate_A) -> 7211.7151 | E17: =(E9*0.35*Non_School_Comm_Rate_A) -> 7211.7151 | F17: =(F9*0.35*Non_School_Comm_Rate_A) -> 7211.7151 | G17: =(G9*0.35*Non_School_Comm_Rate_A) -> 7211.7151 | H17: =(H9*0.35*Non_School_Comm_Rate_A) -> 7211.7151 | I17: =(I9*0.35*Non_School_Comm_Rate_A) -> 7211.7151 | ... AE17: =(AE9*0.35*Non_School_Comm_Rate_A) -> 7211.7151
A18: TIF collection | B18: =IF(AND(B7=0,B8=0),(B10*0.35*Non_School_Comm_Rate_A)+(B11*0.35*Non_School_Comm_Rate_A),IF(AND(B7=0,B8>0),(B10*0.35*Non_School_Comm_Rate_A)+(B11*Apartments_Non_abated*0.35*Non_School_Comm_Rate_A),IF(AND(B7>0,B8=0),(B10*Land_Growth_Non_abated*0.35*Non_School_Comm_Rate_A)+(B11*Apartments_Non_abated*0.35*Non_School_Comm_Rate_A),IF(AND(B7>0,B8>0),(B10*Land_Growth_Non_abated*0.35*Non_School_Comm_Rate_A)+(B11*Apartments_Non_abated*0.35*Non_School_Comm_Rate_A),0)))) -> 0 | C18: =IF(AND(C7=0,C8=0),(C10*0.35*Non_School_Comm_Rate_A)+(C11*0.35*Non_School_Comm_Rate_A),IF(AND(C7=0,C8>0),(C10*0.35*Non_School_Comm_Rate_A)+(C11*Apartments_Non_abated*0.35*Non_School_Comm_Rate_A),IF(AND(C7>0,C8=0),(C10*Land_Growth_Non_abated*0.35*Non_School_Comm_Rate_A)+(C11*Apartments_Non_abated*0.35*Non_School_Comm_Rate_A),IF(AND(C7>0,C8>0),(C10*Land_Growth_Non_abated*0.35*Non_School_Comm_Rate_A)+(C11*Apartments_Non_abated*0.35*Non_School_Comm_Rate_A),0)))) -> 0 | D18: =IF(AND(D7=0,D8=0),(D10*0.35*Non_School_Comm_Rate_A)+(D11*0.35*Non_School_Comm_Rate_A),IF(AND(D7=0,D8>0),(D10*0.35*Non_School_Comm_Rate_A)+(D11*Apartments_Non_abated*0.35*Non_School_Comm_Rate_A),IF(AND(D7>0,D8=0),(D10*Land_Growth_Non_abated*0.35*Non_School_Comm_Rate_A)+(D11*Apartments_Non_abated*0.35*Non_School_Comm_Rate_A),IF(AND(D7>0,D8>0),(D10*Land_Growth_Non_abated*0.35*Non_School_Comm_Rate_A)+(D11*Apartments_Non_abated*0.35*Non_School_Comm_Rate_A),0)))) -> 0 | E18: =IF(AND(E7=0,E8=0),(E10*0.35*Non_School_Comm_Rate_A)+(E11*0.35*Non_School_Comm_Rate_A),IF(AND(E7=0,E8>0),(E10*0.35*Non_School_Comm_Rate_A)+(E11*Apartments_Non_abated*0.35*Non_School_Comm_Rate_A),IF(AND(E7>0,E8=0),(E10*Land_Growth_Non_abated*0.35*Non_School_Comm_Rate_A)+(E11*Apartments_Non_abated*0.35*Non_School_Comm_Rate_A),IF(AND(E7>0,E8>0),(E10*Land_Growth_Non_abated*0.35*Non_School_Comm_Rate_A)+(E11*Apartments_Non_abated*0.35*Non_School_Comm_Rate_A),0)))) -> 0 | F18: =IF(AND(F7=0,F8=0),(F10*0.35*Non_School_Comm_Rate_A)+(F11*0.35*Non_School_Comm_Rate_A),IF(AND(F7=0,F8>0),(F10*0.35*Non_School_Comm_Rate_A)+(F11*Apartments_Non_abated*0.35*Non_School_Comm_Rate_A),IF(AND(F7>0,F8=0),(F10*Land_Growth_Non_abated*0.35*Non_School_Comm_Rate_A)+(F11*Apartments_Non_abated*0.35*Non_School_Comm_Rate_A),IF(AND(F7>0,F8>0),(F10*Land_Growth_Non_abated*0.35*Non_School_Comm_Rate_A)+(F11*Apartments_Non_abated*0.35*Non_School_Comm_Rate_A),0)))) -> 0 | G18: =IF(AND(G7=0,G8=0),(G10*0.35*Non_School_Comm_Rate_A)+(G11*0.35*Non_School_Comm_Rate_A),IF(AND(G7=0,G8>0),(G10*0.35*Non_School_Comm_Rate_A)+(G11*Apartments_Non_abated*0.35*Non_School_Comm_Rate_A),IF(AND(G7>0,G8=0),(G10*Land_Growth_Non_abated*0.35*Non_School_Comm_Rate_A)+(G11*Apartments_Non_abated*0.35*Non_School_Comm_Rate_A),IF(AND(G7>0,G8>0),(G10*Land_Growth_Non_abated*0.35*Non_School_Comm_Rate_A)+(G11*Apartments_Non_abated*0.35*Non_School_Comm_Rate_A),0)))) -> 0 | H18: =IF(AND(H7=0,H8=0),(H10*0.35*Non_School_Comm_Rate_A)+(H11*0.35*Non_School_Comm_Rate_A),IF(AND(H7=0,H8>0),(H10*0.35*Non_School_Comm_Rate_A)+(H11*Apartments_Non_abated*0.35*Non_School_Comm_Rate_A),IF(AND(H7>0,H8=0),(H10*Land_Growth_Non_abated*0.35*Non_School_Comm_Rate_A)+(H11*Apartments_Non_abated*0.35*Non_School_Comm_Rate_A),IF(AND(H7>0,H8>0),(H10*Land_Growth_Non_abated*0.35*Non_School_Comm_Rate_A)+(H11*Apartments_Non_abated*0.35*Non_School_Comm_Rate_A),0)))) -> 0 | I18: =IF(AND(I7=0,I8=0),(I10*0.35*Non_School_Comm_Rate_A)+(I11*0.35*Non_School_Comm_Rate_A),IF(AND(I7=0,I8>0),(I10*0.35*Non_School_Comm_Rate_A)+(I11*Apartments_Non_abated*0.35*Non_School_Comm_Rate_A),IF(AND(I7>0,I8=0),(I10*Land_Growth_Non_abated*0.35*Non_School_Comm_Rate_A)+(I11*Apartments_Non_abated*0.35*Non_School_Comm_Rate_A),IF(AND(I7>0,I8>0),(I10*Land_Growth_Non_abated*0.35*Non_School_Comm_Rate_A)+(I11*Apartments_Non_abated*0.35*Non_School_Comm_Rate_A),0)))) -> 0 | ... AE18: =IF(AND(AE7=0,AE8=0),(AE10*0.35*Non_School_Comm_Rate_A)+(AE11*0.35*Non_School_Comm_Rate_A),IF(AND(AE7=0,AE8>0),(AE10*0.35*Non_School_Comm_Rate_A)+(AE11*Apartments_Non_abated*0.35*Non_School_Comm_Rate_A),IF(AND(AE7>0,AE8=0),(AE10*Land_Growth_Non_abated*0.35*Non_School_Comm_Rate_A)+(AE11*Apartments_Non_abated*0.35*Non_School_Comm_Rate_A),IF(AND(AE7>0,AE8>0),(AE10*Land_Growth_Non_abated*0.35*Non_School_Comm_Rate_A)+(AE11*Apartments_Non_abated*0.35*Non_School_Comm_Rate_A),0)))) -> 486564.39
A19: CDC - land | B19: =IF(B7>0,B10*0.35*Land_Growth_CDC*Full_Comm_Rate_A,0) -> 0 | C19: =IF(C7>0,C10*0.35*Land_Growth_CDC*Full_Comm_Rate_A,0) -> 0 | D19: =IF(D7>0,D10*0.35*Land_Growth_CDC*Full_Comm_Rate_A,0) -> 73872.616 | E19: =IF(E7>0,E10*0.35*Land_Growth_CDC*Full_Comm_Rate_A,0) -> 78304.973 | F19: =IF(F7>0,F10*0.35*Land_Growth_CDC*Full_Comm_Rate_A,0) -> 78304.973 | G19: =IF(G7>0,G10*0.35*Land_Growth_CDC*Full_Comm_Rate_A,0) -> 78304.973 | H19: =IF(H7>0,H10*0.35*Land_Growth_CDC*Full_Comm_Rate_A,0) -> 80654.122 | I19: =IF(I7>0,I10*0.35*Land_Growth_CDC*Full_Comm_Rate_A,0) -> 80654.122 | ... AE19: =IF(AE7>0,AE10*0.35*Land_Growth_CDC*Full_Comm_Rate_A,0) -> 0
A20: CDC - Improvement | B20: =IF(B8>0,B11*0.35*Apartments_CDC*Full_Comm_Rate_A,0) -> 0 | C20: =IF(C8>0,C11*0.35*Apartments_CDC*Full_Comm_Rate_A,0) -> 0 | D20: =IF(D8>0,D11*0.35*Apartments_CDC*Full_Comm_Rate_A,0) -> 541732.52 | E20: =IF(E8>0,E11*0.35*Apartments_CDC*Full_Comm_Rate_A,0) -> 574236.47 | F20: =IF(F8>0,F11*0.35*Apartments_CDC*Full_Comm_Rate_A,0) -> 574236.47 | G20: =IF(G8>0,G11*0.35*Apartments_CDC*Full_Comm_Rate_A,0) -> 574236.47 | H20: =IF(H8>0,H11*0.35*Apartments_CDC*Full_Comm_Rate_A,0) -> 591463.56 | I20: =IF(I8>0,I11*0.35*Apartments_CDC*Full_Comm_Rate_A,0) -> 591463.56 | ... AE20: =IF(AE8>0,AE11*0.35*Apartments_CDC*Full_Comm_Rate_A,0) -> 0
A21: Construction service payments | B21: =IF(SUM(B18:B20)=0,IF(C21=0,IF(SUM(B18:B20)=0,SUM(C18:C20)*0.5,SUM(D18:D20)*0.25),SUM(D18:D20)*0.25),0) -> 153901.28 | C21: =IF(SUM(C18:C20)=0,IF(D21=0,IF(SUM(C18:C20)=0,SUM(D18:D20)*0.5,SUM(E18:E20)*0.25),SUM(E18:E20)*0.25),0) -> 307802.57 | D21: =IF(SUM(D18:D20)=0,IF(E21=0,IF(SUM(D18:D20)=0,SUM(E18:E20)*0.5,SUM(F18:F20)*0.25),SUM(F18:F20)*0.25),0) -> 0 | E21: =IF(SUM(E18:E20)=0,IF(F21=0,IF(SUM(E18:E20)=0,SUM(F18:F20)*0.5,SUM(G18:G20)*0.25),SUM(G18:G20)*0.25),0) -> 0 | F21: =IF(SUM(F18:F20)=0,IF(G21=0,IF(SUM(F18:F20)=0,SUM(G18:G20)*0.5,SUM(H18:H20)*0.25),SUM(H18:H20)*0.25),0) -> 0 | G21: =IF(SUM(G18:G20)=0,IF(H21=0,IF(SUM(G18:G20)=0,SUM(H18:H20)*0.5,SUM(I18:I20)*0.25),SUM(I18:I20)*0.25),0) -> 0 | H21: =IF(SUM(H18:H20)=0,IF(I21=0,IF(SUM(H18:H20)=0,SUM(I18:I20)*0.5,SUM(J18:J20)*0.25),SUM(J18:J20)*0.25),0) -> 0 | I21: =IF(SUM(I18:I20)=0,IF(J21=0,IF(SUM(I18:I20)=0,SUM(J18:J20)*0.5,SUM(K18:K20)*0.25),SUM(K18:K20)*0.25),0) -> 0 | ... AE21: =IF(SUM(AE18:AE20)=0,IF(AF21=0,IF(SUM(AE18:AE20)=0,SUM(AF18:AF20)*0.5,SUM(AG18:AG20)*0.25),SUM(AG18:AG20)*0.25),0) -> 0
A22: Abate. value retained | B22: =IF(B7=0,IF(B8=0,0,(B11*Apartments_Retained*0.35*Full_Comm_Rate_A)),((B10*Land_Growth_Retained*0.35*Full_Comm_Rate_A)+IF(B8=0,0,(B11*Apartments_Retained*0.35*Full_Comm_Rate_A)))) -> 0 | C22: =IF(C7=0,IF(C8=0,0,(C11*Apartments_Retained*0.35*Full_Comm_Rate_A)),((C10*Land_Growth_Retained*0.35*Full_Comm_Rate_A)+IF(C8=0,0,(C11*Apartments_Retained*0.35*Full_Comm_Rate_A)))) -> 0 | D22: =IF(D7=0,IF(D8=0,0,(D11*Apartments_Retained*0.35*Full_Comm_Rate_A)),((D10*Land_Growth_Retained*0.35*Full_Comm_Rate_A)+IF(D8=0,0,(D11*Apartments_Retained*0.35*Full_Comm_Rate_A)))) -> 615605.14 | E22: =IF(E7=0,IF(E8=0,0,(E11*Apartments_Retained*0.35*Full_Comm_Rate_A)),((E10*Land_Growth_Retained*0.35*Full_Comm_Rate_A)+IF(E8=0,0,(E11*Apartments_Retained*0.35*Full_Comm_Rate_A)))) -> 652541.44 | F22: =IF(F7=0,IF(F8=0,0,(F11*Apartments_Retained*0.35*Full_Comm_Rate_A)),((F10*Land_Growth_Retained*0.35*Full_Comm_Rate_A)+IF(F8=0,0,(F11*Apartments_Retained*0.35*Full_Comm_Rate_A)))) -> 652541.44 | G22: =IF(G7=0,IF(G8=0,0,(G11*Apartments_Retained*0.35*Full_Comm_Rate_A)),((G10*Land_Growth_Retained*0.35*Full_Comm_Rate_A)+IF(G8=0,0,(G11*Apartments_Retained*0.35*Full_Comm_Rate_A)))) -> 652541.44 | H22: =IF(H7=0,IF(H8=0,0,(H11*Apartments_Retained*0.35*Full_Comm_Rate_A)),((H10*Land_Growth_Retained*0.35*Full_Comm_Rate_A)+IF(H8=0,0,(H11*Apartments_Retained*0.35*Full_Comm_Rate_A)))) -> 672117.69 | I22: =IF(I7=0,IF(I8=0,0,(I11*Apartments_Retained*0.35*Full_Comm_Rate_A)),((I10*Land_Growth_Retained*0.35*Full_Comm_Rate_A)+IF(I8=0,0,(I11*Apartments_Retained*0.35*Full_Comm_Rate_A)))) -> 672117.69 | ... AE22: =IF(AE7=0,IF(AE8=0,0,(AE11*Apartments_Retained*0.35*Full_Comm_Rate_A)),((AE10*Land_Growth_Retained*0.35*Full_Comm_Rate_A)+IF(AE8=0,0,(AE11*Apartments_Retained*0.35*Full_Comm_Rate_A)))) -> 0
A23: Total Annual Collections | B23: =SUM(B16:B21) -> 181387.1 | C23: =SUM(C16:C21) -> 335288.39 | D23: =SUM(D16:D21) -> 643090.95 | E23: =SUM(E16:E21) -> 680027.26 | F23: =SUM(F16:F21) -> 680027.26 | G23: =SUM(G16:G21) -> 680027.26 | H23: =SUM(H16:H21) -> 699603.51 | I23: =SUM(I16:I21) -> 699603.51 | ... AE23: =SUM(AE16:AE21) -> 1881915.9
A24: TOTAL MINIMUM SERVICE PAYMENTS | B24: =IF(B25=0,SUM(B18:B21),"ERROR") -> 153901.28 | C24: =IF(C25=0,SUM(C18:C21),"ERROR") -> 307802.57 | D24: =IF(D25=0,SUM(D18:D21),"ERROR") -> 615605.14 | E24: =IF(E25=0,SUM(E18:E21),"ERROR") -> 652541.44 | F24: =IF(F25=0,SUM(F18:F21),"ERROR") -> 652541.44 | G24: =IF(G25=0,SUM(G18:G21),"ERROR") -> 652541.44 | H24: =IF(H25=0,SUM(H18:H21),"ERROR") -> 672117.69 | I24: =IF(I25=0,SUM(I18:I21),"ERROR") -> 672117.69 | ... AE24: =IF(AE25=0,SUM(AE18:AE21),"ERROR") -> 486564.39
A25: TAX VALUE TEST (SHOULD EQUAL ZERO) | B25: =SUM(B16:B20,B22)-B14 -> 0 | C25: =SUM(C16:C20,C22)-C14 -> 0 | D25: =SUM(D16:D20,D22)-D14 -> 0 | E25: =SUM(E16:E20,E22)-E14 -> 0 | F25: =SUM(F16:F20,F22)-F14 -> 0 | G25: =SUM(G16:G20,G22)-G14 -> 0 | H25: =SUM(H16:H20,H22)-H14 -> 0 | I25: =SUM(I16:I20,I22)-I14 -> 0 | ... AE25: =SUM(AE16:AE20,AE22)-AE14 -> 0
A27: =Assumptions!$A$13 -> Office
A28: Land abatement year | B28: =IF(Land_Growth_Term>0,1) -> 1 | C28: =IF(Land_Growth_Term>0,B28+1) -> 2 | D28: =IF(Land_Growth_Term>0,C28+1) -> 3 | E28: =IF(Land_Growth_Term>0,D28+1) -> 4 | F28: =IF(Land_Growth_Term>0,E28+1) -> 5 | G28: =IF(Land_Growth_Term>0,F28+1) -> 6 | H28: =IF(Land_Growth_Term>0,G28+1) -> 7 | I28: =IF(Land_Growth_Term>0,H28+1) -> 8 | J28: =IF(Land_Growth_Term>0,I28+1) -> 9 | K28: =IF(Land_Growth_Term>0,J28+1) -> 10
A29: Building abatement year | B29: =IF(Assumptions!$B$14>=B$2,0,IF(Assumptions!$B$14+1=B$2,1,IF(Assumptions!$B$14+15>=B$2,A29+1,0))) -> 0 | C29: =IF(Assumptions!$B$14>=C$2,0,IF(Assumptions!$B$14+1=C$2,1,IF(Assumptions!$B$14+15>=C$2,B29+1,0))) -> 0 | D29: =IF(Assumptions!$B$14>=D$2,0,IF(Assumptions!$B$14+1=D$2,1,IF(Assumptions!$B$14+15>=D$2,C29+1,0))) -> 1 | E29: =IF(Assumptions!$B$14>=E$2,0,IF(Assumptions!$B$14+1=E$2,1,IF(Assumptions!$B$14+15>=E$2,D29+1,0))) -> 2 | F29: =IF(Assumptions!$B$14>=F$2,0,IF(Assumptions!$B$14+1=F$2,1,IF(Assumptions!$B$14+15>=F$2,E29+1,0))) -> 3 | G29: =IF(Assumptions!$B$14>=G$2,0,IF(Assumptions!$B$14+1=G$2,1,IF(Assumptions!$B$14+15>=G$2,F29+1,0))) -> 4 | H29: =IF(Assumptions!$B$14>=H$2,0,IF(Assumptions!$B$14+1=H$2,1,IF(Assumptions!$B$14+15>=H$2,G29+1,0))) -> 5 | I29: =IF(Assumptions!$B$14>=I$2,0,IF(Assumptions!$B$14+1=I$2,1,IF(Assumptions!$B$14+15>=I$2,H29+1,0))) -> 6 | ... AE29: =IF(Assumptions!$B$14>=AE$2,0,IF(Assumptions!$B$14+1=AE$2,1,IF(Assumptions!$B$14+15>=AE$2,AD29+1,0))) -> 0
A30: Base value | B30: =Office_Base_Val -> 139862.5 | C30: =B30 -> 139862.5 | D30: =C30 -> 139862.5 | E30: =D30 -> 139862.5 | F30: =E30 -> 139862.5 | G30: =F30 -> 139862.5 | H30: =G30 -> 139862.5 | I30: =H30 -> 139862.5 | J30: =I30 -> 139862.5 | ... AE30: =AD30 -> 139862.5
A31: Land growth | B31: =IF(B$2<=Assumptions!$B$14,0,IF(B$2=Assumptions!$B$14+1,Office_Land_Growth*(1+B$4),IF(B$2>Assumptions!$B$14,A31*(1+B$3),0))) -> 0 | C31: =IF(C$2<=Assumptions!$B$14,0,IF(C$2=Assumptions!$B$14+1,Office_Land_Growth*(1+C$4),IF(C$2>Assumptions!$B$14,B31*(1+C$3),0))) -> 0 | D31: =IF(D$2<=Assumptions!$B$14,0,IF(D$2=Assumptions!$B$14+1,Office_Land_Growth*(1+D$4),IF(D$2>Assumptions!$B$14,C31*(1+D$3),0))) -> 833080.99 | E31: =IF(E$2<=Assumptions!$B$14,0,IF(E$2=Assumptions!$B$14+1,Office_Land_Growth*(1+E$4),IF(E$2>Assumptions!$B$14,D31*(1+E$3),0))) -> 883065.85 | F31: =IF(F$2<=Assumptions!$B$14,0,IF(F$2=Assumptions!$B$14+1,Office_Land_Growth*(1+F$4),IF(F$2>Assumptions!$B$14,E31*(1+F$3),0))) -> 883065.85 | G31: =IF(G$2<=Assumptions!$B$14,0,IF(G$2=Assumptions!$B$14+1,Office_Land_Growth*(1+G$4),IF(G$2>Assumptions!$B$14,F31*(1+G$3),0))) -> 883065.85 | H31: =IF(H$2<=Assumptions!$B$14,0,IF(H$2=Assumptions!$B$14+1,Office_Land_Growth*(1+H$4),IF(H$2>Assumptions!$B$14,G31*(1+H$3),0))) -> 909557.83 | I31: =IF(I$2<=Assumptions!$B$14,0,IF(I$2=Assumptions!$B$14+1,Office_Land_Growth*(1+I$4),IF(I$2>Assumptions!$B$14,H31*(1+I$3),0))) -> 909557.83 | ... AE31: =IF(AE$2<=Assumptions!$B$14,0,IF(AE$2=Assumptions!$B$14+1,Office_Land_Growth*(1+AE$4),IF(AE$2>Assumptions!$B$14,AD31*(1+AE$3),0))) -> 1254773.8
A32: Improvement value | B32: =IF(B$2<=Assumptions!$B$14,0,IF(B$2=Assumptions!$B$14+1,Office_Impvt_Val*(1+B$4),IF(B$2>Assumptions!$B$14,A32*(1+B$3),0))) -> 0 | C32: =IF(C$2<=Assumptions!$B$14,0,IF(C$2=Assumptions!$B$14+1,Office_Impvt_Val*(1+C$4),IF(C$2>Assumptions!$B$14,B32*(1+C$3),0))) -> 0 | D32: =IF(D$2<=Assumptions!$B$14,0,IF(D$2=Assumptions!$B$14+1,Office_Impvt_Val*(1+D$4),IF(D$2>Assumptions!$B$14,C32*(1+D$3),0))) -> 6109260.6 | E32: =IF(E$2<=Assumptions!$B$14,0,IF(E$2=Assumptions!$B$14+1,Office_Impvt_Val*(1+E$4),IF(E$2>Assumptions!$B$14,D32*(1+E$3),0))) -> 6475816.3 | F32: =IF(F$2<=Assumptions!$B$14,0,IF(F$2=Assumptions!$B$14+1,Office_Impvt_Val*(1+F$4),IF(F$2>Assumptions!$B$14,E32*(1+F$3),0))) -> 6475816.3 | G32: =IF(G$2<=Assumptions!$B$14,0,IF(G$2=Assumptions!$B$14+1,Office_Impvt_Val*(1+G$4),IF(G$2>Assumptions!$B$14,F32*(1+G$3),0))) -> 6475816.3 | H32: =IF(H$2<=Assumptions!$B$14,0,IF(H$2=Assumptions!$B$14+1,Office_Impvt_Val*(1+H$4),IF(H$2>Assumptions!$B$14,G32*(1+H$3),0))) -> 6670090.8 | I32: =IF(I$2<=Assumptions!$B$14,0,IF(I$2=Assumptions!$B$14+1,Office_Impvt_Val*(1+I$4),IF(I$2>Assumptions!$B$14,H32*(1+I$3),0))) -> 6670090.8 | ... AE32: =IF(AE$2<=Assumptions!$B$14,0,IF(AE$2=Assumptions!$B$14+1,Office_Impvt_Val*(1+AE$4),IF(AE$2>Assumptions!$B$14,AD32*(1+AE$3),0))) -> 9201674.8
A33: Full Value Tax
A34: Full value | B34: =SUM(B30:B32) -> 139862.5 | C34: =SUM(C30:C32) -> 139862.5 | D34: =SUM(D30:D32) -> 7082204.1 | E34: =SUM(E30:E32) -> 7498744.6 | F34: =SUM(F30:F32) -> 7498744.6 | G34: =SUM(G30:G32) -> 7498744.6 | H34: =SUM(H30:H32) -> 7719511.1 | I34: =SUM(I30:I32) -> 7719511.1 | ... AE34: =SUM(AE30:AE32) -> 10596311
A35: Full tax | B35: =B34*0.35*Full_Comm_Rate_A -> 4422.0923 | C35: =C34*0.35*Full_Comm_Rate_A -> 4422.0923 | D35: =D34*0.35*Full_Comm_Rate_A -> 223921.07 | E35: =E34*0.35*Full_Comm_Rate_A -> 237091.01 | F35: =F34*0.35*Full_Comm_Rate_A -> 237091.01 | G35: =G34*0.35*Full_Comm_Rate_A -> 237091.01 | H35: =H34*0.35*Full_Comm_Rate_A -> 244071.08 | I35: =I34*0.35*Full_Comm_Rate_A -> 244071.08 | ... AE35: =AE34*0.35*Full_Comm_Rate_A -> 335028.09
A36: Collection Items
A37: Tax to school | B37: =IF(AND(B28=0,B29=0),(B30*0.35*School_Comm_Rate_A)+(B31*0.35*School_Comm_Rate_A)+(B32*0.35*School_Comm_Rate_A),IF(AND(B28=0,B29>0),(B30*0.35*School_Comm_Rate_A)+(B31*0.35*School_Comm_Rate_A)+(B32*Office_Non_abated*0.35*School_Comm_Rate_A),IF(AND(B28>0,B29=0),(B30*0.35*School_Comm_Rate_A)+(B31*Land_Growth_Non_abated*0.35*School_Comm_Rate_A)+(B32*0.35*School_Comm_Rate_A),IF(AND(B28>0,B29>0),(B30*0.35*School_Comm_Rate_A)+(B31*Land_Growth_Non_abated*0.35*School_Comm_Rate_A)+(B32*Office_Non_abated*0.35*School_Comm_Rate_A),0)))) -> 3261.826 | C37: =IF(AND(C28=0,C29=0),(C30*0.35*School_Comm_Rate_A)+(C31*0.35*School_Comm_Rate_A)+(C32*0.35*School_Comm_Rate_A),IF(AND(C28=0,C29>0),(C30*0.35*School_Comm_Rate_A)+(C31*0.35*School_Comm_Rate_A)+(C32*Office_Non_abated*0.35*School_Comm_Rate_A),IF(AND(C28>0,C29=0),(C30*0.35*School_Comm_Rate_A)+(C31*Land_Growth_Non_abated*0.35*School_Comm_Rate_A)+(C32*0.35*School_Comm_Rate_A),IF(AND(C28>0,C29>0),(C30*0.35*School_Comm_Rate_A)+(C31*Land_Growth_Non_abated*0.35*School_Comm_Rate_A)+(C32*Office_Non_abated*0.35*School_Comm_Rate_A),0)))) -> 3261.826 | D37: =IF(AND(D28=0,D29=0),(D30*0.35*School_Comm_Rate_A)+(D31*0.35*School_Comm_Rate_A)+(D32*0.35*School_Comm_Rate_A),IF(AND(D28=0,D29>0),(D30*0.35*School_Comm_Rate_A)+(D31*0.35*School_Comm_Rate_A)+(D32*Office_Non_abated*0.35*School_Comm_Rate_A),IF(AND(D28>0,D29=0),(D30*0.35*School_Comm_Rate_A)+(D31*Land_Growth_Non_abated*0.35*School_Comm_Rate_A)+(D32*0.35*School_Comm_Rate_A),IF(AND(D28>0,D29>0),(D30*0.35*School_Comm_Rate_A)+(D31*Land_Growth_Non_abated*0.35*School_Comm_Rate_A)+(D32*Office_Non_abated*0.35*School_Comm_Rate_A),0)))) -> 38881.355 | E37: =IF(AND(E28=0,E29=0),(E30*0.35*School_Comm_Rate_A)+(E31*0.35*School_Comm_Rate_A)+(E32*0.35*School_Comm_Rate_A),IF(AND(E28=0,E29>0),(E30*0.35*School_Comm_Rate_A)+(E31*0.35*School_Comm_Rate_A)+(E32*Office_Non_abated*0.35*School_Comm_Rate_A),IF(AND(E28>0,E29=0),(E30*0.35*School_Comm_Rate_A)+(E31*Land_Growth_Non_abated*0.35*School_Comm_Rate_A)+(E32*0.35*School_Comm_Rate_A),IF(AND(E28>0,E29>0),(E30*0.35*School_Comm_Rate_A)+(E31*Land_Growth_Non_abated*0.35*School_Comm_Rate_A)+(E32*Office_Non_abated*0.35*School_Comm_Rate_A),0)))) -> 41018.527 | F37: =IF(AND(F28=0,F29=0),(F30*0.35*School_Comm_Rate_A)+(F31*0.35*School_Comm_Rate_A)+(F32*0.35*School_Comm_Rate_A),IF(AND(F28=0,F29>0),(F30*0.35*School_Comm_Rate_A)+(F31*0.35*School_Comm_Rate_A)+(F32*Office_Non_abated*0.35*School_Comm_Rate_A),IF(AND(F28>0,F29=0),(F30*0.35*School_Comm_Rate_A)+(F31*Land_Growth_Non_abated*0.35*School_Comm_Rate_A)+(F32*0.35*School_Comm_Rate_A),IF(AND(F28>0,F29>0),(F30*0.35*School_Comm_Rate_A)+(F31*Land_Growth_Non_abated*0.35*School_Comm_Rate_A)+(F32*Office_Non_abated*0.35*School_Comm_Rate_A),0)))) -> 41018.527 | G37: =IF(AND(G28=0,G29=0),(G30*0.35*School_Comm_Rate_A)+(G31*0.35*School_Comm_Rate_A)+(G32*0.35*School_Comm_Rate_A),IF(AND(G28=0,G29>0),(G30*0.35*School_Comm_Rate_A)+(G31*0.35*School_Comm_Rate_A)+(G32*Office_Non_abated*0.35*School_Comm_Rate_A),IF(AND(G28>0,G29=0),(G30*0.35*School_Comm_Rate_A)+(G31*Land_Growth_Non_abated*0.35*School_Comm_Rate_A)+(G32*0.35*School_Comm_Rate_A),IF(AND(G28>0,G29>0),(G30*0.35*School_Comm_Rate_A)+(G31*Land_Growth_Non_abated*0.35*School_Comm_Rate_A)+(G32*Office_Non_abated*0.35*School_Comm_Rate_A),0)))) -> 41018.527 | H37: =IF(AND(H28=0,H29=0),(H30*0.35*School_Comm_Rate_A)+(H31*0.35*School_Comm_Rate_A)+(H32*0.35*School_Comm_Rate_A),IF(AND(H28=0,H29>0),(H30*0.35*School_Comm_Rate_A)+(H31*0.35*School_Comm_Rate_A)+(H32*Office_Non_abated*0.35*School_Comm_Rate_A),IF(AND(H28>0,H29=0),(H30*0.35*School_Comm_Rate_A)+(H31*Land_Growth_Non_abated*0.35*School_Comm_Rate_A)+(H32*0.35*School_Comm_Rate_A),IF(AND(H28>0,H29>0),(H30*0.35*School_Comm_Rate_A)+(H31*Land_Growth_Non_abated*0.35*School_Comm_Rate_A)+(H32*Office_Non_abated*0.35*School_Comm_Rate_A),0)))) -> 42151.228 | I37: =IF(AND(I28=0,I29=0),(I30*0.35*School_Comm_Rate_A)+(I31*0.35*School_Comm_Rate_A)+(I32*0.35*School_Comm_Rate_A),IF(AND(I28=0,I29>0),(I30*0.35*School_Comm_Rate_A)+(I31*0.35*School_Comm_Rate_A)+(I32*Office_Non_abated*0.35*School_Comm_Rate_A),IF(AND(I28>0,I29=0),(I30*0.35*School_Comm_Rate_A)+(I31*Land_Growth_Non_abated*0.35*School_Comm_Rate_A)+(I32*0.35*School_Comm_Rate_A),IF(AND(I28>0,I29>0),(I30*0.35*School_Comm_Rate_A)+(I31*Land_Growth_Non_abated*0.35*School_Comm_Rate_A)+(I32*Office_Non_abated*0.35*School_Comm_Rate_A),0)))) -> 42151.228 | ... AE37: =IF(AND(AE28=0,AE29=0),(AE30*0.35*School_Comm_Rate_A)+(AE31*0.35*School_Comm_Rate_A)+(AE32*0.35*School_Comm_Rate_A),IF(AND(AE28=0,AE29>0),(AE30*0.35*School_Comm_Rate_A)+(AE31*0.35*School_Comm_Rate_A)+(AE32*Office_Non_abated*0.35*School_Comm_Rate_A),IF(AND(AE28>0,AE29=0),(AE30*0.35*School_Comm_Rate_A)+(AE31*Land_Growth_Non_abated*0.35*School_Comm_Rate_A)+(AE32*0.35*School_Comm_Rate_A),IF(AND(AE28>0,AE29>0),(AE30*0.35*School_Comm_Rate_A)+(AE31*Land_Growth_Non_abated*0.35*School_Comm_Rate_A)+(AE32*Office_Non_abated*0.35*School_Comm_Rate_A),0)))) -> 247123.59
A38: Tax to non school | B38: =(B30*0.35*Non_School_Comm_Rate_A) -> 1160.2663 | C38: =(C30*0.35*Non_School_Comm_Rate_A) -> 1160.2663 | D38: =(D30*0.35*Non_School_Comm_Rate_A) -> 1160.2663 | E38: =(E30*0.35*Non_School_Comm_Rate_A) -> 1160.2663 | F38: =(F30*0.35*Non_School_Comm_Rate_A) -> 1160.2663 | G38: =(G30*0.35*Non_School_Comm_Rate_A) -> 1160.2663 | H38: =(H30*0.35*Non_School_Comm_Rate_A) -> 1160.2663 | I38: =(I30*0.35*Non_School_Comm_Rate_A) -> 1160.2663 | ... AE38: =(AE30*0.35*Non_School_Comm_Rate_A) -> 1160.2663
A39: TIF collection | B39: =IF(AND(B28=0,B29=0),(B31*0.35*Non_School_Comm_Rate_A)+(B32*0.35*Non_School_Comm_Rate_A),IF(AND(B28=0,B29>0),(B31*0.35*Non_School_Comm_Rate_A)+(B32*Office_Non_abated*0.35*Non_School_Comm_Rate_A),IF(AND(B28>0,B29=0),(B31*Land_Growth_Non_abated*0.35*Non_School_Comm_Rate_A)+(B32*Office_Non_abated*0.35*Non_School_Comm_Rate_A),IF(AND(B28>0,B29>0),(B31*Land_Growth_Non_abated*0.35*Non_School_Comm_Rate_A)+(B32*Office_Non_abated*0.35*Non_School_Comm_Rate_A),0)))) -> 0 | C39: =IF(AND(C28=0,C29=0),(C31*0.35*Non_School_Comm_Rate_A)+(C32*0.35*Non_School_Comm_Rate_A),IF(AND(C28=0,C29>0),(C31*0.35*Non_School_Comm_Rate_A)+(C32*Office_Non_abated*0.35*Non_School_Comm_Rate_A),IF(AND(C28>0,C29=0),(C31*Land_Growth_Non_abated*0.35*Non_School_Comm_Rate_A)+(C32*Office_Non_abated*0.35*Non_School_Comm_Rate_A),IF(AND(C28>0,C29>0),(C31*Land_Growth_Non_abated*0.35*Non_School_Comm_Rate_A)+(C32*Office_Non_abated*0.35*Non_School_Comm_Rate_A),0)))) -> 0 | D39: =IF(AND(D28=0,D29=0),(D31*0.35*Non_School_Comm_Rate_A)+(D32*0.35*Non_School_Comm_Rate_A),IF(AND(D28=0,D29>0),(D31*0.35*Non_School_Comm_Rate_A)+(D32*Office_Non_abated*0.35*Non_School_Comm_Rate_A),IF(AND(D28>0,D29=0),(D31*Land_Growth_Non_abated*0.35*Non_School_Comm_Rate_A)+(D32*Office_Non_abated*0.35*Non_School_Comm_Rate_A),IF(AND(D28>0,D29>0),(D31*Land_Growth_Non_abated*0.35*Non_School_Comm_Rate_A)+(D32*Office_Non_abated*0.35*Non_School_Comm_Rate_A),0)))) -> 12670.246 | E39: =IF(AND(E28=0,E29=0),(E31*0.35*Non_School_Comm_Rate_A)+(E32*0.35*Non_School_Comm_Rate_A),IF(AND(E28=0,E29>0),(E31*0.35*Non_School_Comm_Rate_A)+(E32*Office_Non_abated*0.35*Non_School_Comm_Rate_A),IF(AND(E28>0,E29=0),(E31*Land_Growth_Non_abated*0.35*Non_School_Comm_Rate_A)+(E32*Office_Non_abated*0.35*Non_School_Comm_Rate_A),IF(AND(E28>0,E29>0),(E31*Land_Growth_Non_abated*0.35*Non_School_Comm_Rate_A)+(E32*Office_Non_abated*0.35*Non_School_Comm_Rate_A),0)))) -> 13430.461 | F39: =IF(AND(F28=0,F29=0),(F31*0.35*Non_School_Comm_Rate_A)+(F32*0.35*Non_School_Comm_Rate_A),IF(AND(F28=0,F29>0),(F31*0.35*Non_School_Comm_Rate_A)+(F32*Office_Non_abated*0.35*Non_School_Comm_Rate_A),IF(AND(F28>0,F29=0),(F31*Land_Growth_Non_abated*0.35*Non_School_Comm_Rate_A)+(F32*Office_Non_abated*0.35*Non_School_Comm_Rate_A),IF(AND(F28>0,F29>0),(F31*Land_Growth_Non_abated*0.35*Non_School_Comm_Rate_A)+(F32*Office_Non_abated*0.35*Non_School_Comm_Rate_A),0)))) -> 13430.461 | G39: =IF(AND(G28=0,G29=0),(G31*0.35*Non_School_Comm_Rate_A)+(G32*0.35*Non_School_Comm_Rate_A),IF(AND(G28=0,G29>0),(G31*0.35*Non_School_Comm_Rate_A)+(G32*Office_Non_abated*0.35*Non_School_Comm_Rate_A),IF(AND(G28>0,G29=0),(G31*Land_Growth_Non_abated*0.35*Non_School_Comm_Rate_A)+(G32*Office_Non_abated*0.35*Non_School_Comm_Rate_A),IF(AND(G28>0,G29>0),(G31*Land_Growth_Non_abated*0.35*Non_School_Comm_Rate_A)+(G32*Office_Non_abated*0.35*Non_School_Comm_Rate_A),0)))) -> 13430.461 | H39: =IF(AND(H28=0,H29=0),(H31*0.35*Non_School_Comm_Rate_A)+(H32*0.35*Non_School_Comm_Rate_A),IF(AND(H28=0,H29>0),(H31*0.35*Non_School_Comm_Rate_A)+(H32*Office_Non_abated*0.35*Non_School_Comm_Rate_A),IF(AND(H28>0,H29=0),(H31*Land_Growth_Non_abated*0.35*Non_School_Comm_Rate_A)+(H32*Office_Non_abated*0.35*Non_School_Comm_Rate_A),IF(AND(H28>0,H29>0),(H31*Land_Growth_Non_abated*0.35*Non_School_Comm_Rate_A)+(H32*Office_Non_abated*0.35*Non_School_Comm_Rate_A),0)))) -> 13833.375 | I39: =IF(AND(I28=0,I29=0),(I31*0.35*Non_School_Comm_Rate_A)+(I32*0.35*Non_School_Comm_Rate_A),IF(AND(I28=0,I29>0),(I31*0.35*Non_School_Comm_Rate_A)+(I32*Office_Non_abated*0.35*Non_School_Comm_Rate_A),IF(AND(I28>0,I29=0),(I31*Land_Growth_Non_abated*0.35*Non_School_Comm_Rate_A)+(I32*Office_Non_abated*0.35*Non_School_Comm_Rate_A),IF(AND(I28>0,I29>0),(I31*Land_Growth_Non_abated*0.35*Non_School_Comm_Rate_A)+(I32*Office_Non_abated*0.35*Non_School_Comm_Rate_A),0)))) -> 13833.375 | ... AE39: =IF(AND(AE28=0,AE29=0),(AE31*0.35*Non_School_Comm_Rate_A)+(AE32*0.35*Non_School_Comm_Rate_A),IF(AND(AE28=0,AE29>0),(AE31*0.35*Non_School_Comm_Rate_A)+(AE32*Office_Non_abated*0.35*Non_School_Comm_Rate_A),IF(AND(AE28>0,AE29=0),(AE31*Land_Growth_Non_abated*0.35*Non_School_Comm_Rate_A)+(AE32*Office_Non_abated*0.35*Non_School_Comm_Rate_A),IF(AND(AE28>0,AE29>0),(AE31*Land_Growth_Non_abated*0.35*Non_School_Comm_Rate_A)+(AE32*Office_Non_abated*0.35*Non_School_Comm_Rate_A),0)))) -> 86744.23
A40: CDC - land | B40: =IF(B28>0,B31*0.35*Land_Growth_CDC*Full_Comm_Rate_A,0) -> 0 | C40: =IF(C28>0,C31*0.35*Land_Growth_CDC*Full_Comm_Rate_A,0) -> 0 | D40: =IF(D28>0,D31*0.35*Land_Growth_CDC*Full_Comm_Rate_A,0) -> 13169.939 | E40: =IF(E28>0,E31*0.35*Land_Growth_CDC*Full_Comm_Rate_A,0) -> 13960.135 | F40: =IF(F28>0,F31*0.35*Land_Growth_CDC*Full_Comm_Rate_A,0) -> 13960.135 | G40: =IF(G28>0,G31*0.35*Land_Growth_CDC*Full_Comm_Rate_A,0) -> 13960.135 | H40: =IF(H28>0,H31*0.35*Land_Growth_CDC*Full_Comm_Rate_A,0) -> 14378.939 | I40: =IF(I28>0,I31*0.35*Land_Growth_CDC*Full_Comm_Rate_A,0) -> 14378.939 | ... AE40: =IF(AE28>0,AE31*0.35*Land_Growth_CDC*Full_Comm_Rate_A,0) -> 0
A41: CDC - Improvement | B41: =IF(B29>0,B32*0.35*Office_CDC*Full_Comm_Rate_A,0) -> 0 | C41: =IF(C29>0,C32*0.35*Office_CDC*Full_Comm_Rate_A,0) -> 0 | D41: =IF(D29>0,D32*0.35*Office_CDC*Full_Comm_Rate_A,0) -> 48289.775 | E41: =IF(E29>0,E32*0.35*Office_CDC*Full_Comm_Rate_A,0) -> 51187.162 | F41: =IF(F29>0,F32*0.35*Office_CDC*Full_Comm_Rate_A,0) -> 51187.162 | G41: =IF(G29>0,G32*0.35*Office_CDC*Full_Comm_Rate_A,0) -> 51187.162 | H41: =IF(H29>0,H32*0.35*Office_CDC*Full_Comm_Rate_A,0) -> 52722.776 | I41: =IF(I29>0,I32*0.35*Office_CDC*Full_Comm_Rate_A,0) -> 52722.776 | ... AE41: =IF(AE29>0,AE32*0.35*Office_CDC*Full_Comm_Rate_A,0) -> 0
A42: Construction service payments | B42: =IF(SUM(B39:B41)=0,IF(C42=0,IF(SUM(B39:B41)=0,SUM(C39:C41)*0.5,SUM(D39:D41)*0.25),SUM(D39:D41)*0.25),0) -> 18532.49 | C42: =IF(SUM(C39:C41)=0,IF(D42=0,IF(SUM(C39:C41)=0,SUM(D39:D41)*0.5,SUM(E39:E41)*0.25),SUM(E39:E41)*0.25),0) -> 37064.98 | D42: =IF(SUM(D39:D41)=0,IF(E42=0,IF(SUM(D39:D41)=0,SUM(E39:E41)*0.5,SUM(F39:F41)*0.25),SUM(F39:F41)*0.25),0) -> 0 | E42: =IF(SUM(E39:E41)=0,IF(F42=0,IF(SUM(E39:E41)=0,SUM(F39:F41)*0.5,SUM(G39:G41)*0.25),SUM(G39:G41)*0.25),0) -> 0 | F42: =IF(SUM(F39:F41)=0,IF(G42=0,IF(SUM(F39:F41)=0,SUM(G39:G41)*0.5,SUM(H39:H41)*0.25),SUM(H39:H41)*0.25),0) -> 0 | G42: =IF(SUM(G39:G41)=0,IF(H42=0,IF(SUM(G39:G41)=0,SUM(H39:H41)*0.5,SUM(I39:I41)*0.25),SUM(I39:I41)*0.25),0) -> 0 | H42: =IF(SUM(H39:H41)=0,IF(I42=0,IF(SUM(H39:H41)=0,SUM(I39:I41)*0.5,SUM(J39:J41)*0.25),SUM(J39:J41)*0.25),0) -> 0 | I42: =IF(SUM(I39:I41)=0,IF(J42=0,IF(SUM(I39:I41)=0,SUM(J39:J41)*0.5,SUM(K39:K41)*0.25),SUM(K39:K41)*0.25),0) -> 0 | ... AE42: =IF(SUM(AE39:AE41)=0,IF(AF42=0,IF(SUM(AE39:AE41)=0,SUM(AF39:AF41)*0.5,SUM(AG39:AG41)*0.25),SUM(AG39:AG41)*0.25),0) -> 0
...

Sheet Revenue Summary
A1: Index Year | B1: 1 | C1: =B1+1 -> 2 | D1: =C1+1 -> 3 | E1: =D1+1 -> 4 | F1: =E1+1 -> 5 | G1: =F1+1 -> 6 | H1: =G1+1 -> 7 | I1: =H1+1 -> 8 | J1: =I1+1 -> 9 | ... AE1: =AD1+1 -> 30
A2: Tax Year | B2: =Calculations!B1 -> 2020 | C2: =B2+1 -> 2021 | D2: =C2+1 -> 2022 | E2: =D2+1 -> 2023 | F2: =E2+1 -> 2024 | G2: =F2+1 -> 2025 | H2: =G2+1 -> 2026 | I2: =H2+1 -> 2027 | J2: =I2+1 -> 2028 | ... AE2: =AD2+1 -> 2049
A3: Collection Year | B3: =Calculations!B2 -> 2021 | C3: =Calculations!C2 -> 2022 | D3: =Calculations!D2 -> 2023 | E3: =Calculations!E2 -> 2024 | F3: =Calculations!F2 -> 2025 | G3: =Calculations!G2 -> 2026 | H3: =Calculations!H2 -> 2027 | I3: =Calculations!I2 -> 2028 | ... AE3: =Calculations!AE2 -> 2050
A4: MINIMUM SERVICE PAYMENTS ON PHASE 1 - CONSTRUCTION
A5: =Calculations!A93 -> Apartments | B5: =Calculations!B24 -> 153901.28 | C5: =Calculations!C24 -> 307802.57 | D5: =Calculations!D24 -> 615605.14 | E5: =Calculations!E24 -> 652541.44 | F5: =Calculations!F24 -> 652541.44 | G5: =Calculations!G24 -> 652541.44 | H5: =Calculations!H24 -> 672117.69 | I5: =Calculations!I24 -> 672117.69 | ... AE5: =Calculations!AE24 -> 486564.39
A6: =Calculations!A94 -> Office | B6: =Calculations!B45 -> 18532.49 | C6: =Calculations!C45 -> 37064.98 | D6: =Calculations!D45 -> 74129.96 | E6: =Calculations!E45 -> 78577.758 | F6: =Calculations!F45 -> 78577.758 | G6: =Calculations!G45 -> 78577.758 | H6: =Calculations!H45 -> 80935.09 | I6: =Calculations!I45 -> 80935.09 | ... AE6: =Calculations!AE45 -> 86744.23
A7: =Calculations!A95 -> Single-Family Homes | B7: =Calculations!B67 -> 0 | C7: =Calculations!C67 -> 0 | D7: =Calculations!D67 -> 0 | E7: =Calculations!E67 -> 132901.92 | F7: =Calculations!F67 -> 132901.92 | G7: =Calculations!G67 -> 132901.92 | H7: =Calculations!H67 -> 136888.98 | I7: =Calculations!I67 -> 136888.98 | ... AE7: =Calculations!AE67 -> 106608
A8: =Calculations!A96 -> Condos | B8: =Calculations!B89 -> 0 | C8: =Calculations!C89 -> 0 | D8: =Calculations!D89 -> 0 | E8: =Calculations!E89 -> 260855.44 | F8: =Calculations!F89 -> 260855.44 | G8: =Calculations!G89 -> 260855.44 | H8: =Calculations!H89 -> 268681.1 | I8: =Calculations!I89 -> 268681.1 | ... AE8: =Calculations!AE89 -> 209246.62
A9: TOTAL MINIMUM SERVICE PAYMENTS | B9: =SUM(B5:B8) -> 172433.77 | C9: =SUM(C5:C8) -> 344867.55 | D9: =SUM(D5:D8) -> 689735.1 | E9: =SUM(E5:E8) -> 1124876.6 | F9: =SUM(F5:F8) -> 1124876.6 | G9: =SUM(G5:G8) -> 1124876.6 | H9: =SUM(H5:H8) -> 1158622.9 | I9: =SUM(I5:I8) -> 1158622.9 | ... AE9: =SUM(AE5:AE8) -> 889163.25
A11: Debt Coverage
A12: Cash Flow | B12: =B9/Assumptions!$G$16 -> 156757.98 | C12: =C9/Assumptions!$G$16 -> 313515.95 | D12: =D9/Assumptions!$G$16 -> 627031.9 | E12: =E9/Assumptions!$G$16 -> 1022615.1 | F12: =F9/Assumptions!$G$16 -> 1022615.1 | G12: =G9/Assumptions!$G$16 -> 1022615.1 | H12: =H9/Assumptions!$G$16 -> 1053293.5 | I12: =I9/Assumptions!$G$16 -> 1053293.5 | ... AE12: =AE9/Assumptions!$G$16 -> 808330.22
A13: Remaining | B13: =B9-B12 -> 15675.798 | C13: =C9-C12 -> 31351.595 | D13: =D9-D12 -> 62703.19 | E13: =E9-E12 -> 102261.51 | F13: =F9-F12 -> 102261.51 | G13: =G9-G12 -> 102261.51 | H13: =H9-H12 -> 105329.35 | I13: =I9-I12 -> 105329.35 | ... AE13: =AE9-AE12 -> 80833.022
A15: A Bond
A16: Cash Flow | B16: =B12 -> 156757.98 | C16: =C12 -> 313515.95 | D16: =D12 -> 627031.9 | E16: =E12 -> 1022615.1 | F16: =F12 -> 1022615.1 | G16: =G12 -> 1022615.1 | H16: =H12 -> 1053293.5 | I16: =I12 -> 1053293.5 | ... AE16: =AE12 -> 808330.22
A17: Reserve | B17: 0 | C17: 0 | D17: 0 | E17: 0 | F17: 0 | G17: 0 | H17: 0 | I17: 0 | J17: 0 | K17: 0 | L17: 0 | M17: 0 | N17: 0 | O17: 0 | P17: 0 | Q17: 0 | R17: 0 | S17: 0 | T17: 0 | U17: 0 | V17: 0 | W17: 0 | X17: 0 | Y17: 0 | Z17: 0 | AA17: 0 | AB17: 0 | AC17: 0 | AD17: 0
A18: Surplus
A19: Excess from A (Debt Coverage) | B19: =B13 -> 15675.798 | C19: =C13 -> 31351.595 | D19: =D13 -> 62703.19 | E19: =E13 -> 102261.51 | F19: =F13 -> 102261.51 | G19: =G13 -> 102261.51 | H19: =H13 -> 105329.35 | I19: =I13 -> 105329.35 | ... AE19: =AE13 -> 80833.022
